
I20241202 18:41:21 1149017 dinov2 train.py:276] Starting training from iteration 0
Traceback (most recent call last):
  File "/home/ge54xof/dino-tum/dinov2/train/train.py", line 388, in <module>
    main(args)
  File "/home/ge54xof/dino-tum/dinov2/train/train.py", line 383, in main
    do_train(cfg, model, resume=not args.no_resume)
  File "/home/ge54xof/dino-tum/dinov2/train/train.py", line 345, in do_train
    , "koleo_loss": loss_dict_reduced['koleo_loss'], "dino_local_crops_loss": loss_dict_reduced['dino_local_crops_loss']
KeyError: 'koleo_loss'